Traceback (most recent call last):
  File "graph.py", line 189, in <module>
    cs.wrapper(main, sys.argv[1])
IndexError: list index out of range
